Traceback (most recent call last):
  File "/cluster/home/rsidhu/code/datacenter_monitoring/curl_getData.py", line 9, in <module>
    ganglia_req = requests.get('http://129.107.255.31:8080/atlas/ganglia')
  File "/usr/lib/python2.6/site-packages/requests/api.py", line 67, in get
    return request('get', url, params=params, **kwargs)
  File "/usr/lib/python2.6/site-packages/requests/api.py", line 53, in request
    return session.request(method=method, url=url, **kwargs)
  File "/usr/lib/python2.6/site-packages/requests/sessions.py", line 468, in request
    resp = self.send(prep, **send_kwargs)
  File "/usr/lib/python2.6/site-packages/requests/sessions.py", line 576, in send
    r = adapter.send(request, **kwargs)
  File "/usr/lib/python2.6/site-packages/requests/adapters.py", line 437, in send
    raise ConnectionError(e, request=request)
requests.exceptions.ConnectionError: HTTPConnectionPool(host='129.107.255.31', port=8080): Max retries exceeded with url: /atlas/ganglia (Caused by NewConnectionError('<requests.packages.urllib3.connection.HTTPConnection object at 0x295afd0>: Failed to establish a new connection: [Errno 111] Connection refused',))
